<?xml version="1.0" ?>
<robot name="diffbot" xmlns:xacro="http://ros.org/wiki/xacro">

  <material name="black">
    <color rgba="0 0 0 1"/>
  </material>
  <material name="white">
    <color rgba="1 1 1 1"/>
  </material>

  <link name="base_footprint"/>

  <joint name="base_joint" type="fixed">
    <parent link="base_footprint"/>
    <child link="base_link"/>
    <origin xyz="0.0 0.0 0.01" rpy="0 0 0"/>
  </joint>

  <link name="base_link">
    <collision>
      <origin xyz="0 0 0" rpy="0 0 0"/>
      <geometry>
        <box size="0.140 0.140 0.143"/>
      </geometry>
    </collision>

    <inertial>
      <origin xyz="0 0 0" rpy="0 0 0"/>
      <mass value="1"/>
      <inertia ixx="1.0" ixy="1.0" ixz="1.0"
               iyy="1.0" iyz="1.0"
               izz="1.0" />
    </inertial>
  </link>

  <joint name="wheel_joint_left" type="continuous">
    <parent link="base_link"/>
    <child link="wheel_link_left"/>
    <origin xyz="0 0.15 0.03" rpy="-1.5707963268 0 0"/>
    <axis xyz="0 0 1"/>
  </joint>

  <link name="wheel_link_left">
    <collision>
      <origin xyz="0 0 0" rpy="0 0 0"/>
      <geometry>  
        <cylinder length="0.018" radius="0.04"/>
      </geometry>
    </collision>

    <inertial>
      <origin xyz="0 0 0" rpy="0 0 0"/>
      <mass value="1"/>
      <inertia ixx="1.0" ixy="1.0" ixz="1.0"
               iyy="1.0" iyz="1.0"
               izz="1.0" />
      </inertial>
    
    <visual>
      <origin rpy="0.0 0 0" xyz="0 0 0"/>
      <geometry>
        <mesh filename="package://diffbot_description/meshes/wheel.stl"/>
      </geometry>
      <material name="white"/>
    </visual>
  </link>

  <joint name="wheel_joint_right" type="continuous">
    <parent link="base_link"/>
    <child link="wheel_link_right"/>
    <origin xyz="0 -0.15 0.03" rpy="1.5707963268 0 0"/>
    <axis xyz="0 0 1"/>
  </joint>

  <link name="wheel_link_right">
    <collision>
      <origin xyz="0 0 0" rpy="0 0 0"/>
      <geometry>
        <cylinder length="0.018" radius="0.04"/>
      </geometry>
    </collision>

    <inertial>
      <origin xyz="0 0 0" rpy="0 0 0"/>
      <mass value="1"/>
      <inertia ixx="1.0" ixy="1.0" ixz="1.0"
               iyy="1.0" iyz="1.0"
               izz="1.0" />
      </inertial>

    <visual>
      <origin rpy="0.0 0 0" xyz="0 0 0"/>
      <geometry>
        <mesh filename="package://diffbot_description/meshes/wheel.stl"/>
      </geometry>
      <material name="white"/>
    </visual>
  </link>

</robot>